Workbook

Sheet README
B2: OWASP Browser Security Verification Standard (BSVS)
B3: Version 0.1: Draft requirements register generated from the community outline
B4: Jerry Hoff
B5: Purpose | C5: A verifiable set of technical, governance, and policy controls for reducing browser-layer risk in enterprise organizations. Peer to OWASP ASVS (applications) and MASVS (mobile).
B6: How to use | C6: Each row on the Requirements sheet is one independently assessable control phrased as 'Verify that…'. Filter by Chapter, Control Type, or Level to work your slice. The Status and Notes columns are provided for organizations using this file as a self-assessment register.
B7: Requirement ID | C7: BSVS-<chapter>.<section>.<item>, e.g. BSVS-3.1.2.
B8: Control types | C8: Technical (enforced by configuration or tooling) · Governance (process, ownership, review) · Policy (documented rules for people).
B9: Draft status | C9: This is a v0.1 outline for community review. Mapping columns (ATT&CK, CWE, CIS, NIST CSF) are intentionally blank for community completion. Contribute via the OWASP Browser Security Project on GitHub.
B11: Assessment Levels
B12: L1 — Baseline | C12: Minimum hygiene for any organization using browsers for business. Applies to all organizations.
B13: L2 — Managed | C13: Organizations with centrally managed fleets, sensitive data, or compliance obligations. Most enterprises. Includes L1.
B14: L3 — High Assurance | C14: Regulated, high-security, or high-value-target environments (finance, health, government, critical infrastructure). Includes L1 and L2.
B16: Chapters
B17: V1 | C17: Browser Governance, Ownership & Policy (12 requirements)
B18: V2 | C18: Deployment, Configuration & Update Management (18 requirements)
B19: V3 | C19: Extension & Plugin Management (12 requirements)
B20: V4 | C20: Identity, Session & Credential Protection (13 requirements)
B21: V5 | C21: Data Protection & Exfiltration Control (11 requirements)
B22: V6 | C22: Threat Protection & Safe Browsing (12 requirements)
B23: V7 | C23: AI & Agentic Browsing (11 requirements)
B24: V8 | C24: Monitoring, Telemetry & Incident Response (10 requirements)

Sheet Requirements
A1: Req ID | B1: Chapter | C1: Section | D1: Requirement | E1: Control Type | F1: Level | G1: L1 | H1: L2 | I1: L3 | J1: ATT&CK / ATLAS | K1: CWE | L1: CIS Benchmark | M1: NIST CSF | N1: Status | O1: Notes
A2: BSVS-1.1.1 | B2: V1: Browser Governance, Ownership & Policy | C2: 1.1 Ownership & Accountability | D2: Verify that a named owner (role or team) is assigned responsibility for browser security policy and configuration across the organization | E2: Governance | F2: L1 | G2: ✓ | H2: ✓ | I2: ✓
A3: BSVS-1.1.2 | B3: V1: Browser Governance, Ownership & Policy | C3: 1.1 Ownership & Accountability | D3: Verify that browser security responsibilities are documented across endpoint, identity, network, and application security functions with defined handoffs | E3: Governance | F3: L2 | H3: ✓ | I3: ✓
A4: BSVS-1.1.3 | B4: V1: Browser Governance, Ownership & Policy | C4: 1.1 Ownership & Accountability | D4: Verify that browser risk is represented in the organization's risk register and reviewed on a defined cadence | E4: Governance | F4: L2 | H4: ✓ | I4: ✓
A5: BSVS-1.2.1 | B5: V1: Browser Governance, Ownership & Policy | C5: 1.2 Policy Coverage | D5: Verify that an acceptable use policy covers browser usage, including sanctioned browsers, personal profile use, and extension installation | E5: Policy | F5: L1 | G5: ✓ | H5: ✓ | I5: ✓
A6: BSVS-1.2.2 | B6: V1: Browser Governance, Ownership & Policy | C6: 1.2 Policy Coverage | D6: Verify that policy defines which browsers and versions are approved for business use, and prohibits unmanaged browsers for access to sensitive systems | E6: Policy | F6: L2 | H6: ✓ | I6: ✓
A7: BSVS-1.2.3 | B7: V1: Browser Governance, Ownership & Policy | C7: 1.2 Policy Coverage | D7: Verify that policy addresses BYOD and unmanaged-device browser access to corporate resources, with technical enforcement defined | E7: Policy | F7: L2 | H7: ✓ | I7: ✓
A8: BSVS-1.2.4 | B8: V1: Browser Governance, Ownership & Policy | C8: 1.2 Policy Coverage | D8: Verify that GenAI usage via the browser (chatbots, sidebars, agents) is covered by policy, including data classification rules for what may be submitted | E8: Policy | F8: L2 | H8: ✓ | I8: ✓
A9: BSVS-1.3.1 | B9: V1: Browser Governance, Ownership & Policy | C9: 1.3 Standards, Exceptions & Review | D9: Verify that a documented exception process exists for deviations from browser policy, with expiry dates and compensating controls | E9: Governance | F9: L2 | H9: ✓ | I9: ✓
A10: BSVS-1.3.2 | B10: V1: Browser Governance, Ownership & Policy | C10: 1.3 Standards, Exceptions & Review | D10: Verify that browser security policies and configurations are reviewed at least annually and after significant browser platform changes | E10: Governance | F10: L2 | H10: ✓ | I10: ✓
A11: BSVS-1.3.3 | B11: V1: Browser Governance, Ownership & Policy | C11: 1.3 Standards, Exceptions & Review | D11: Verify that browser controls are included in internal audit or independent assessment scope | E11: Governance | F11: L3 | I11: ✓
A12: BSVS-1.4.1 | B12: V1: Browser Governance, Ownership & Policy | C12: 1.4 Vendor & Procurement Governance | D12: Verify that security requirements (including this standard) are considered when procuring enterprise browsers, browser security tooling, or browser-based SaaS | E12: Governance | F12: L2 | H12: ✓ | I12: ✓
A13: BSVS-1.4.2 | B13: V1: Browser Governance, Ownership & Policy | C13: 1.4 Vendor & Procurement Governance | D13: Verify that third-party browser components (enterprise browsers, extension vendors) are covered by the organization's third-party risk process | E13: Governance | F13: L3 | I13: ✓
A14: BSVS-2.1.1 | B14: V2: Deployment, Configuration & Update Management | C14: 2.1 Inventory & Fleet Visibility | D14: Verify that the organization maintains an inventory of browsers (product and version) in use across managed endpoints | E14: Technical | F14: L1 | G14: ✓ | H14: ✓ | I14: ✓
A15: BSVS-2.1.2 | B15: V2: Deployment, Configuration & Update Management | C15: 2.1 Inventory & Fleet Visibility | D15: Verify that unmanaged or unapproved browsers on managed endpoints can be detected and remediated | E15: Technical | F15: L2 | H15: ✓ | I15: ✓
A16: BSVS-2.1.3 | B16: V2: Deployment, Configuration & Update Management | C16: 2.1 Inventory & Fleet Visibility | D16: Verify that browser access to sensitive applications from outside the managed fleet is identified (e.g., via IdP or application logs) | E16: Technical | F16: L3 | I16: ✓
A17: BSVS-2.2.1 | B17: V2: Deployment, Configuration & Update Management | C17: 2.2 Centralized Configuration Management | D17: Verify that browser security settings are enforced centrally (e.g., via management policy) rather than relying on user-controlled defaults | E17: Technical | F17: L1 | G17: ✓ | H17: ✓ | I17: ✓
A18: BSVS-2.2.2 | B18: V2: Deployment, Configuration & Update Management | C18: 2.2 Centralized Configuration Management | D18: Verify that enforced configuration is derived from a documented hardening baseline (e.g., CIS Benchmarks) with deviations recorded | E18: Technical | F18: L2 | H18: ✓ | I18: ✓
A19: BSVS-2.2.3 | B19: V2: Deployment, Configuration & Update Management | C19: 2.2 Centralized Configuration Management | D19: Verify that users cannot disable or override security-relevant policies (e.g., Safe Browsing, extension controls, update settings) | E19: Technical | F19: L2 | H19: ✓ | I19: ✓
A20: BSVS-2.2.4 | B20: V2: Deployment, Configuration & Update Management | C20: 2.2 Centralized Configuration Management | D20: Verify that configuration drift from the approved baseline is detected and alerted | E20: Technical | F20: L3 | I20: ✓
A21: BSVS-2.3.1 | B21: V2: Deployment, Configuration & Update Management | C21: 2.3 Update & Vulnerability Management | D21: Verify that automatic browser updates are enabled and cannot be disabled by users | E21: Technical | F21: L1 | G21: ✓ | H21: ✓ | I21: ✓
A22: BSVS-2.3.2 | B22: V2: Deployment, Configuration & Update Management | C22: 2.3 Update & Vulnerability Management | D22: Verify that browser versions across the fleet reach the latest stable release within a defined SLA, with reporting on laggards | E22: Technical | F22: L2 | H22: ✓ | I22: ✓
A23: BSVS-2.3.3 | B23: V2: Deployment, Configuration & Update Management | C23: 2.3 Update & Vulnerability Management | D23: Verify that a process exists for emergency deployment of browser patches for actively exploited vulnerabilities (0-days) | E23: Technical | F23: L2 | H23: ✓ | I23: ✓
A24: BSVS-2.3.4 | B24: V2: Deployment, Configuration & Update Management | C24: 2.3 Update & Vulnerability Management | D24: Verify that browser and extension vulnerabilities are included in the organization's vulnerability management program | E24: Governance | F24: L2 | H24: ✓ | I24: ✓
A25: BSVS-2.3.5 | B25: V2: Deployment, Configuration & Update Management | C25: 2.3 Update & Vulnerability Management | D25: Verify that relaunch/restart is enforced within a defined window after update download so patches take effect | E25: Technical | F25: L3 | I25: ✓
A26: BSVS-2.4.1 | B26: V2: Deployment, Configuration & Update Management | C26: 2.4 Feature & API Surface Reduction | D26: Verify that unneeded high-risk browser capabilities (e.g., WebUSB, WebSerial, WebBluetooth, remote debugging) are disabled by policy where there is no business need | E26: Technical | F26: L2 | H26: ✓ | I26: ✓
A27: BSVS-2.4.2 | B27: V2: Deployment, Configuration & Update Management | C27: 2.4 Feature & API Surface Reduction | D27: Verify that developer tools and browser flags are restricted on endpoints or for users where there is no business need | E27: Technical | F27: L2 | H27: ✓ | I27: ✓
A28: BSVS-2.4.3 | B28: V2: Deployment, Configuration & Update Management | C28: 2.4 Feature & API Surface Reduction | D28: Verify that legacy or deprecated protocols and features (e.g., insecure TLS versions, deprecated plugin interfaces) are disabled fleet-wide | E28: Technical | F28: L3 | I28: ✓
A29: BSVS-2.5.1 | B29: V2: Deployment, Configuration & Update Management | C29: 2.5 Profiles & Environment Separation | D29: Verify that corporate browser profiles are separated from personal profiles, with corporate data confined to managed profiles | E29: Technical | F29: L2 | H29: ✓ | I29: ✓
A30: BSVS-2.5.2 | B30: V2: Deployment, Configuration & Update Management | C30: 2.5 Profiles & Environment Separation | D30: Verify that sync of corporate profile data (passwords, history, tabs) to personal accounts is blocked | E30: Technical | F30: L2 | H30: ✓ | I30: ✓
A31: BSVS-2.5.3 | B31: V2: Deployment, Configuration & Update Management | C31: 2.5 Profiles & Environment Separation | D31: Verify that high-risk browsing (unknown sites) can be isolated from sessions accessing sensitive applications (e.g., separate profiles, isolation technology) | E31: Technical | F31: L3 | I31: ✓
A32: BSVS-3.1.1 | B32: V3: Extension & Plugin Management | C32: 3.1 Installation Control | D32: Verify that users cannot install extensions from arbitrary or unofficial sources (sideloading, developer mode) on managed browsers | E32: Technical | F32: L1 | G32: ✓ | H32: ✓ | I32: ✓
A33: BSVS-3.1.2 | B33: V3: Extension & Plugin Management | C33: 3.1 Installation Control | D33: Verify that extension installation is restricted to an approved allowlist, or that a defined blocklist plus permission-based restrictions are enforced | E33: Technical | F33: L2 | H33: ✓ | I33: ✓
A34: BSVS-3.1.3 | B34: V3: Extension & Plugin Management | C34: 3.1 Installation Control | D34: Verify that extension installation requests follow a documented review-and-approval workflow | E34: Technical | F34: L3 | I34: ✓
A35: BSVS-3.2.1 | B35: V3: Extension & Plugin Management | C35: 3.2 Review & Risk Assessment | D35: Verify that a documented process exists for assessing extensions before approval, covering permissions requested, publisher reputation, and data handling | E35: Governance | F35: L2 | H35: ✓ | I35: ✓
A36: BSVS-3.2.2 | B36: V3: Extension & Plugin Management | C36: 3.2 Review & Risk Assessment | D36: Verify that extensions requesting high-risk permissions (e.g., access to all sites, reading browsing data, clipboard, native messaging) receive heightened review | E36: Technical | F36: L2 | H36: ✓ | I36: ✓
A37: BSVS-3.2.3 | B37: V3: Extension & Plugin Management | C37: 3.2 Review & Risk Assessment | D37: Verify that approved extensions are re-assessed on ownership change, permission escalation, or a defined periodic cadence | E37: Technical | F37: L3 | I37: ✓
A38: BSVS-3.3.1 | B38: V3: Extension & Plugin Management | C38: 3.3 Runtime & Lifecycle Control | D38: Verify that installed extensions across the fleet are inventoried, including version and permission set | E38: Technical | F38: L2 | H38: ✓ | I38: ✓
A39: BSVS-3.3.2 | B39: V3: Extension & Plugin Management | C39: 3.3 Runtime & Lifecycle Control | D39: Verify that an extension can be force-removed or disabled fleet-wide within a defined SLA when found malicious or compromised | E39: Technical | F39: L2 | H39: ✓ | I39: ✓
A40: BSVS-3.3.3 | B40: V3: Extension & Plugin Management | C40: 3.3 Runtime & Lifecycle Control | D40: Verify that extension permission changes on update are detected and trigger re-review | E40: Technical | F40: L2 | H40: ✓ | I40: ✓
...

Sheet Summary
B2: Requirements by Chapter and Level
B4: Chapter | C4: L1 | D4: L2 | E4: L3 | F4: Total
B5: V1: Browser Governance, Ownership & Policy | C5: =COUNTIFS(Requirements!$B$2:$B$100,$B5,Requirements!$F$2:$F$100,"L1") -> 2 | D5: =COUNTIFS(Requirements!$B$2:$B$100,$B5,Requirements!$F$2:$F$100,"L2") -> 8 | E5: =COUNTIFS(Requirements!$B$2:$B$100,$B5,Requirements!$F$2:$F$100,"L3") -> 2 | F5: =SUM(C5:E5) -> 12
B6: V2: Deployment, Configuration & Update Management | C6: =COUNTIFS(Requirements!$B$2:$B$100,$B6,Requirements!$F$2:$F$100,"L1") -> 3 | D6: =COUNTIFS(Requirements!$B$2:$B$100,$B6,Requirements!$F$2:$F$100,"L2") -> 10 | E6: =COUNTIFS(Requirements!$B$2:$B$100,$B6,Requirements!$F$2:$F$100,"L3") -> 5 | F6: =SUM(C6:E6) -> 18
B7: V3: Extension & Plugin Management | C7: =COUNTIFS(Requirements!$B$2:$B$100,$B7,Requirements!$F$2:$F$100,"L1") -> 1 | D7: =COUNTIFS(Requirements!$B$2:$B$100,$B7,Requirements!$F$2:$F$100,"L2") -> 7 | E7: =COUNTIFS(Requirements!$B$2:$B$100,$B7,Requirements!$F$2:$F$100,"L3") -> 4 | F7: =SUM(C7:E7) -> 12
B8: V4: Identity, Session & Credential Protection | C8: =COUNTIFS(Requirements!$B$2:$B$100,$B8,Requirements!$F$2:$F$100,"L1") -> 2 | D8: =COUNTIFS(Requirements!$B$2:$B$100,$B8,Requirements!$F$2:$F$100,"L2") -> 7 | E8: =COUNTIFS(Requirements!$B$2:$B$100,$B8,Requirements!$F$2:$F$100,"L3") -> 4 | F8: =SUM(C8:E8) -> 13
B9: V5: Data Protection & Exfiltration Control | C9: =COUNTIFS(Requirements!$B$2:$B$100,$B9,Requirements!$F$2:$F$100,"L1") -> 0 | D9: =COUNTIFS(Requirements!$B$2:$B$100,$B9,Requirements!$F$2:$F$100,"L2") -> 6 | E9: =COUNTIFS(Requirements!$B$2:$B$100,$B9,Requirements!$F$2:$F$100,"L3") -> 5 | F9: =SUM(C9:E9) -> 11
B10: V6: Threat Protection & Safe Browsing | C10: =COUNTIFS(Requirements!$B$2:$B$100,$B10,Requirements!$F$2:$F$100,"L1") -> 4 | D10: =COUNTIFS(Requirements!$B$2:$B$100,$B10,Requirements!$F$2:$F$100,"L2") -> 6 | E10: =COUNTIFS(Requirements!$B$2:$B$100,$B10,Requirements!$F$2:$F$100,"L3") -> 2 | F10: =SUM(C10:E10) -> 12
B11: V7: AI & Agentic Browsing | C11: =COUNTIFS(Requirements!$B$2:$B$100,$B11,Requirements!$F$2:$F$100,"L1") -> 0 | D11: =COUNTIFS(Requirements!$B$2:$B$100,$B11,Requirements!$F$2:$F$100,"L2") -> 7 | E11: =COUNTIFS(Requirements!$B$2:$B$100,$B11,Requirements!$F$2:$F$100,"L3") -> 4 | F11: =SUM(C11:E11) -> 11
B12: V8: Monitoring, Telemetry & Incident Response | C12: =COUNTIFS(Requirements!$B$2:$B$100,$B12,Requirements!$F$2:$F$100,"L1") -> 0 | D12: =COUNTIFS(Requirements!$B$2:$B$100,$B12,Requirements!$F$2:$F$100,"L2") -> 6 | E12: =COUNTIFS(Requirements!$B$2:$B$100,$B12,Requirements!$F$2:$F$100,"L3") -> 4 | F12: =SUM(C12:E12) -> 10
B13: Total | C13: =SUM(C5:C12) -> 12 | D13: =SUM(D5:D12) -> 57 | E13: =SUM(E5:E12) -> 30 | F13: =SUM(F5:F12) -> 99
B15: Requirements by Control Type
B16: Control Type | C16: Count
B17: Technical | C17: =COUNTIF(Requirements!$E$2:$E$100,"*Technical*") -> 72
B18: Governance | C18: =COUNTIF(Requirements!$E$2:$E$100,"*Governance*") -> 22
B19: Policy | C19: =COUNTIF(Requirements!$E$2:$E$100,"*Policy*") -> 5
B21: Note: 'Level' shows the tier at which a requirement first applies; levels are cumulative (checkmarks in the L1–L3 columns on the Requirements sheet show all tiers where it applies).
